Workbook

Sheet EXC-350PC
B2: CONTROL DE COMBUSTIBLE Y HORAS MAQUINA
A3: PROYECTO: | B3: SERVICIO DE ELABORACION DE FICHA TECNICA DEFINITIVA Y DESCOLMATACION POR EL ESTADO DE EMERGENCIA EN EL RIO PALPA-SECTOR TAMBO, EN EL DISTRITO DE PALPA, PROVINCIA DE PALPA, DEPARTAMENTO DE ICA
A4: MAQUINARIA: | B4: EXCAVADORA KOMATSU 350PC
A5: OPERADOR: | B5: JULIO MAXIMO GARCIA CCENTE
B6: SAMUEL CASAVILCA
A7: UBICACIÓN: | B7: TAMBO
A9: PARTE DIARIO | B9: FECHA | C9: HOROMETRO ABASTECIMIENTO | D9: HOROMETRO INICIAL | E9: HOROMETRO FINAL | F9: HORAS TRABAJADAS | G9: COMBUSTIBLE | H9: Rendimeinto GalXhra | I9: OBSERVACION
A10: 501 | B10: 45854 | C10: =+D10 -> 11623.3 | D10: 11623.3 | E10: 11632.1 | F10: =+E10-D10 -> 8.8 | G10: 154.99 | I10: Primer abastecimiento en carretera
A11: 502 | B11: 45855 | C11: 11632.1 | D11: =+E10 -> 11632.1 | E11: 11641.6 | F11: =IF(D11="","",E11-D11) -> 9.5 | G11: 50 | I11: Falta llenar
A12: 503 | B12: 45856 | C12: =+C11+F11 -> 11641.6 | D12: =+E11 -> 11641.6 | E12: 11650.2 | F12: =IF(D12="","",E12-D12) -> 8.6 | G12: 52.027 | I12: Falta llenar 7am
A13: 503 | B13: 45856 | C13: =+C12+4 -> 11645.6 | F13: =IF(D13="","",E13-D13) | G13: 52.39 | I13: Falta llenar 1pm
A14: 503 | B14: 45856 | C14: 11650.2 | F14: =IF(D14="","",E14-D14) | G14: 52.2278 | I14: Falta llenar 7pm
A15: 504 | B15: 45857 | D15: =+E12 -> 11650.2 | E15: 11659 | F15: =IF(D15="","",E15-D15) -> 8.8
A16: 505 | B16: 45858 | D16: =+E15 -> 11659 | E16: 11666.4 | F16: =IF(D16="","",E16-D16) -> 7.4
A17: 506 | B17: 45859 | C17: 11666.6 | D17: =+E16 -> 11666.4 | E17: 11676 | F17: =IF(D17="","",E17-D17) -> 9.6 | G17: 72.83 | I17: TANQUE LLENO
C18: =+C17-C10 -> 43.3 | G18: =SUM(G11:G17) -> 279.4748 | H18: =+G18/C18 -> 6.4543834 | I18: CONTROL
A19: 507 | B19: 45860 | C19: 11676.1 | D19: =+E17 -> 11676 | E19: 11682 | F19: =IF(D19="","",E19-D19) -> 6 | G19: 70.36 | H19: =+G19/(C19-C17) -> 7.4063158 | I19: TANQUE LLENO
A20: 201 | B20: 45860 | D20: =+E19 -> 11682 | E20: 11687 | F20: =IF(D20="","",E20-D20) -> 5 | I20: Operador Samuel Casavilca/turno tarde
A21: 508 | B21: 45861 | D21: =+E20 -> 11687 | E21: 11694.7 | F21: =IF(D21="","",E21-D21) -> 7.7
A22: 202 | B22: 45861 | C22: 11695 | D22: =+E21 -> 11694.7 | E22: 11700.8 | F22: =IF(D22="","",E22-D22) -> 6.1 | G22: =95 -> 95 | I22: Operador Samuel Casavilca/turno tarde
A23: 509 | B23: 45862 | D23: =+E22 -> 11700.8 | E23: 11709.4 | F23: =IF(D23="","",E23-D23) -> 8.6
A24: 204 | B24: 45862 | C24: 11710.6 | D24: =+E23 -> 11709.4 | E24: 11717.1 | F24: =IF(D24="","",E24-D24) -> 7.7 | G24: 119.82 | I24: Operador Samuel Casavilca/turno tarde/TANQUE LLENO
C25: =+C24-C19 -> 34.5 | F25: =IF(D25="","",E25-D25) | G25: =+G24+G22 -> 214.82 | H25: =+G25/C25 -> 6.2266667 | I25: CONTROL
A26: 510 | B26: 45863 | C26: 11725.6 | D26: =+E24 -> 11717.1 | E26: 11725.6 | F26: =IF(D26="","",E26-D26) -> 8.5 | G26: 118.76 | H26: =+G26/(C26-C24) -> 7.9173333 | I26: TANQUE LLENO
A27: 205 | B27: 45863 | D27: =+E26 -> 11725.6 | E27: 11735.8 | F27: =IF(D27="","",E27-D27) -> 10.2 | I27: Operador Samuel Casavilca/turno tard/Tanque lleno
A28: 511 | B28: 45864 | C28: 11741.2 | D28: =+E27 -> 11735.8 | E28: 11742.3 | F28: =IF(D28="","",E28-D28) -> 6.5 | G28: 124.36 | H28: =+G28/(C28-C26) -> 7.9717949 | I28: TANQUE LLENO | K28: LITROS POR GALON
A29: 206 | B29: 45864 | D29: =+E28 -> 11742.3 | E29: 11749.4 | F29: =IF(D29="","",E29-D29) -> 7.1 | I29: Operador Samuel Casavilca/turno tard
A30: 512 | B30: 45868 | D30: =+E29 -> 11749.4 | E30: 11754.3 | F30: =IF(D30="","",E30-D30) -> 4.9
A31: 208 | B31: 45868 | C31: 11757.4 | D31: =+E30 -> 11754.3 | E31: 11762.7 | F31: =IF(D31="","",E31-D31) -> 8.4 | G31: 82 | H31: =+G31/(C31-C28) -> 5.0617284 | I31: Operador Samuel Casavilca/turno tarde no lleno tanque
A32: 513 | B32: 45869 | C32: 11767 | D32: =+E31 -> 11762.7 | E32: 11771.8 | F32: =IF(D32="","",E32-D32) -> 9.1 | G32: 101.47 | H32: =+G32/(C32-C31) -> 10.569792 | K32: =+J17/J78 -> 0
A33: 207 | B33: 45869 | D33: =+E32 -> 11771.8 | E33: 11780.8 | F33: =IF(D33="","",E33-D33) -> 9 | I33: Operador Samuel Casavilca/turno tarde no lleno tanque
B34: 45870 | D34: =+E33 -> 11780.8
B35: 45870 | D35: 11782.1 | E35: 11782.1 | F35: =IF(D35="","",E35-D35) -> 0
B36: 45871 | C36: 11782.1 | D36: =+E35 -> 11782.1 | F36: =IF(D36="","",E36-D36) -> -11782.1 | G36: 116.75 | I36: No lleno el tanque
B37: 45871 | D37: 11791.1 | E37: 11795.6 | F37: =IF(D37="","",E37-D37) -> 4.5
B38: 45872 | C38: 11795.7 | D38: 11801.9 | E38: 11807.4 | F38: =IF(D38="","",E38-D38) -> 5.5 | G38: 57.781 | I38: No lleno el tanque
B39: 45872 | C39: 11801.8 | F39: =IF(D39="","",E39-D39) | G39: 110 | I39: No lleno el tanque
B40: 45873 | C40: 11812.1 | G40: 76.95 | H40: =+G40/(C40-C39) -> 7.4708738 | I40: Lleno tanque
B42: 45873 | D42: 11816.2 | E42: 11824.1 | F42: =IF(D42="","",E42-D42) -> 7.9
B43: 45874 | C43: 11828.7 | G43: 99.88 | H43: =+G43/(C43-C40) -> 6.0168675 | I43: Lleno tanque
...

Sheet EXC. DOOSAN
B2: CONTROL DE COMBUSTIBLE Y HORAS MAQUINA
A3: PROYECTO: | B3: SERVICIO DE ELABORACION DE FICHA TECNICA DEFINITIVA Y DESCOLMATACION POR EL ESTADO DE EMERGENCIA EN EL RIO GRANDE-SECTOR PINTO, EN EL DISTRITO DE RIO GRANDE, PROVINCIA DE PALPA, DEPARTAMENTO DE ICA
A4: MAQUINARIA: | B4: EXCAVADORA DOOSAN 3400 DX 340 LCA M SERIE DHKCECAPPD0005343 | K4: =10.6+8.8+9.7+4.8 -> 33.9 | L4: =+K4*7 -> 237.3
A5: OPERADOR: | B5: RONALD BENDEZU CONDORI
A6: UBICACIÓN: | B6: DISTRITO DE RIO GRANDE | K6: =+K8*2 -> 34.666
L7: =52/3 -> 17.333333
K8: 17.333 | L8: =+K8*3 -> 51.999
A9: PARTE DIARIO | B9: FECHA | C9: HOROMETRO ABASTECIMIENTO | D9: HOROMETRO INICIAL | E9: HOROMETRO FINAL | F9: HORAS TRABAJADAS | G9: COMBUSTIBLE | H9: CONSUMO X HORA | I9: RENDIMIENTO Gal X Hr | J9: OBSERVACION
B10: 45846 | C10: 88882.5 | D10: =+C10 -> 88882.5 | E10: 88887.3 | F10: =IF(D10="","",E10-D10) -> 4.8 | H10: =IF(G10="","",ROUND(G10/F10,2)) | J10: Se inicio las labores a las 1 pm
B11: 45847 | C11: 88889.75 | D11: =+E10 -> 88887.3 | E11: 88897 | F11: =IF(D11="","",E11-D11) -> 9.7 | I11: =G11/(C11-C10) -> 0
B12: 45848 | C12: 88897 | D12: =+E11 -> 88897 | E12: 88905.8 | F12: =+E12-D12 -> 8.8 | G12: 17.26 | J12: Se compró 51.78 gln Doosan y la Komatsu, no lleno
B13: 45849 | C13: 88907 | D13: =+E12 -> 88905.8 | E13: 88916.4 | F13: =+E13-D13 -> 10.6 | G13: 108 | J13: Se abasteció con motocarga 01 cilindro +3 bidones
B14: 45850 | D14: =+E13 -> 88916.4 | E14: 88924.5 | F14: =+E14-D14 -> 8.1 | G14: 0
A15: 690 | B15: 45852 | C15: 88924.5 | D15: 88924.5 | E15: 88934.2 | F15: =+E15-D15 -> 9.7 | G15: =51+16 -> 67 | J15: Falta llenar/Saldo del dia sabado/mañana 6:00am
A16: 690 | B16: 45852 | C16: 88934.2 | F16: 0 | G16: 90.267 | J16: Tanque lleno se abseteció con cubo en la tarde 6:00pm
C17: =+C16-C10 -> 51.7 | G17: =+G16+G15+G13+G12 -> 282.527 | I17: =+G17/C17 -> 5.4647389 | J17: CONTROL
A18: 692 | B18: 45853 | D18: =+E15 -> 88934.2 | E18: 88944.3 | F18: =+E18-D18 -> 10.1
A19: 662 | B19: 45854 | C19: 88948.6 | D19: =+E18 -> 88944.3 | E19: 88948.6 | F19: =+E19-D19 -> 4.3 | G19: 94.3 | J19: Falta llenar | K19: 72.96
A20: 683 | B20: 45855 | D20: =+E19 -> 88948.6 | E20: 88959.2 | F20: =+E20-D20 -> 10.6 | K20: =180-G19 -> 85.7
A21: 701 | B21: 45856 | C21: 88965 | D21: =+E20 -> 88959.2 | E21: 88969.5 | F21: =+E21-D21 -> 10.3 | G21: 39.99
A22: 703 | B22: 45857 | C22: 88970 | D22: =+E21 -> 88969.5 | E22: 88977.2 | F22: =+E22-D22 -> 7.7 | G22: 76
A23: 704 | B23: 45859 | C23: 88981.3 | D23: =+E22 -> 88977.2 | E23: 88987.6 | F23: =+E23-D23 -> 10.4 | G23: 81.8 | J23: TANQUE LLENO
C24: =+C23-C16 -> 47.1 | G24: =SUM(G18:G23) -> 292.09 | I24: =+G24/C24 -> 6.2014862 | J24: CONTROL
A25: 705 | B25: 45860 | C25: 88897.3 | D25: 88897.6 | E25: =+D25+9.7 -> 88907.3 | F25: =+E25-D25 -> 9.7 | G25: 83 | J25: Falta llenar
A26: 706 | B26: 45861 | C26: 88904.1 | D26: =+E25 -> 88907.3 | E26: =+D26+10.3 -> 88917.6 | F26: =+E26-D26 -> 10.3 | G26: 76
A27: 707 | B27: 45862 | D27: =+E26 -> 88917.6 | E27: =+D27+9.9 -> 88927.5 | F27: =+E27-D27 -> 9.9
A28: 708 | B28: 45863 | C28: =+C25+23 -> 88920.3 | D28: =+E27 -> 88927.5 | E28: =+D28+10.4 -> 88937.9 | F28: =+E28-D28 -> 10.4 | G28: 95.46 | L28: =30.25+25.3 -> 55.55
A29: 709 | B29: 45864 | C29: 88927.9 | D29: =+E28 -> 88937.9 | E29: 88938 | F29: =+E29-D29 -> 0.1 | G29: 62.48 | J29: Tanque lleno
C30: =+C29-C25 -> 30.6 | G30: =+G29+G28+G26 -> 233.94 | I30: =+G30/C30 -> 7.645098 | J30: CONTROL
A31: 710 | B31: 45868 | C31: 88943.4 | D31: =+E29 -> 88938 | E31: =+D32 -> 88946.7 | F31: =+E31-D31 -> 8.7 | G31: 86.3 | I31: =+G31/(C31-C29) -> 5.5677419 | J31: FALTA LLENAR
A32: 711 | B32: 45869 | D32: 88946.7 | E32: 88956 | F32: =+E32-D32 -> 9.3 | J32: Maquina en mantenimiento
B33: 45871 | C33: 88956.8 | D33: =+E32 -> 88956 | G33: 46.19
B34: 45872
B35: 45873 | C35: 88957.6 | G35: 54.43
B36: 45874 | C36: 88969 | G36: 76.72 | J36: Tanque lleno
C37: =+C36-C29 -> 41.1 | G37: =+G36+G35+G33+G31 -> 263.64 | I37: =+G37/C37 -> 6.4145985 | J37: CONTROL
B38: 45875 | C38: 88979.6 | G38: 43.48
B39: 45876 | C39: 88991.2 | G39: 110 | J39: Abastecimiento interno Kobelco a Doosan110 gln
C40: =+C39-C36 -> 22.2 | G40: =+G39+G38 -> 153.48 | I40: =+G40/C40 -> 6.9135135 | J40: CONTROL
B41: 45877 | C41: 89005.7 | G41: 90 | J41: Tanque lleno
...

Sheet Camioneta serv
B2: CONTROL DE COMBUSTIBLE Y HORAS MAQUINA
A3: PROYECTO: | B3: SERVICIO DE RESTABLECIMIENTO DE DEFENSA RIBEREÑA, SECTOR VIZCAS
A4: MAQUINARIA: | B4: EXCAVADORA KOBELCO SK-350 -B SERIE YC08U2284
A5: OPERADOR: | B5: NN/AGUILAR
A6: UBICACIÓN: | B6: CENTRO POBLADO DE VIZCAS
A8: PARTE DIARIO | B8: FECHA | C8: HOROMETRO ABASTECIMIENTO | D8: HOROMETRO INICIAL | E8: HOROMETRO FINAL | F8: HORAS TRABAJADAS | G8: COMBUSTIBLE | H8: CONSUMO X HORA | I8: OBSERVACION
B9: 45845
B10: 45846 | G10: 5
B11: 45850 | G11: 5
B12: 45852 | G12: 5
B13: 45853 | G13: 4
B14: 45854
B15: 45855 | G15: 5
B16: 45872 | G16: 5
F18: =IF(D18="","",E18-D18) | H18: =IF(G18="","",ROUND(G18/F18,2))
A19: Total | F19: =SUM(F9:F18) -> 0 | G19: =SUM(G9:G18) -> 29

Sheet EXC. Kobelco SK-350
B2: CONTROL DE COMBUSTIBLE Y HORAS MAQUINA
A3: PROYECTO: | B3: SERVICIO DE ELABORACION DE FICHA TECNICA DEFINITIVA Y DESCOLMATACION POR EL ESTADO DE EMERGENCIA EN EL RIO VISCAZ-SECTOR VISCAZ, EN EL DISTRITO DE PALPA, PROVINCIA DE PALPA, DEPARTAMENTO DE ICA
A4: MAQUINARIA: | B4: EXCAVADORA KOBELCO SK-350 -B SERIE YC08U2284
A5: OPERADOR: | B5: MANUEL NOMBERTO CHAVEZ
A6: UBICACIÓN: | B6: CENTRO POBLADO DE VIZCAS
A8: PARTE DIARIO | B8: FECHA | C8: HOROMETRO ABASTECIMIENTO | D8: HOROMETRO INICIAL | E8: HOROMETRO FINAL | F8: HORAS TRABAJADAS | G8: COMBUSTIBLE | H8: CONSUMO X HORA | I8: OBSERVACION
A9: 219 | B9: 45845 | C9: 10380.1 | D9: 10380.1 | E9: 10388 | F9: =+E9-D9 -> 7.9 | I9: Ingresó con tanque lleno
A10: 220 | B10: 45846 | C10: 10392.8 | D10: =+E9 -> 10388 | E10: 10396.6 | F10: =+E10-D10 -> 8.6 | G10: 79.06 | I10: Faltaba por llenar
A11: 222 | B11: 45847 | C11: 10401.6 | D11: =+E10 -> 10396.6 | E11: 10405.6 | F11: =+E11-D11 -> 9 | G11: 39.9 | I11: Faltaba por llenar
A12: 223 | B12: 45848 | D12: =+E11 -> 10405.6 | E12: 10415.6 | F12: =+E12-D12 -> 10
A13: 224 | B13: 45849 | C13: 10415.8 | D13: =+E12 -> 10415.6 | E13: 10424.3 | F13: =+E13-D13 -> 8.7 | G13: 70 | I13: Faltaba por llenar
A14: 225 | B14: 45850 | C14: 10424.5 | D14: =+E13 -> 10424.3 | E14: 10430.6 | F14: =+E14-D14 -> 6.3 | G14: 90 | I14: Faltaba por llenar
A15: 901 | B15: 45852 | C15: 10436.1 | D15: =+E14 -> 10430.6 | E15: 10439.8 | F15: =+E15-D15 -> 9.2 | G15: 80 | I15: se envió 170 galones distribucion pendiente
A16: 902 | B16: 45853 | C16: 10442.3 | D16: =+E15 -> 10439.8 | E16: 10449.4 | F16: =+E16-D16 -> 9.6 | G16: 70 | I16: Tanque lleno se abaseteció a las 7am
C17: =+C16-C9 -> 62.2 | G17: =SUM(G10:G16) -> 428.96 | H17: =+G17/C17 -> 6.896463 | I17: CONTROL
A18: 902 | B18: 45853 | C18: 10445.5 | F18: =+E18-D18 -> 0 | G18: 12 | I18: Faltaba llenar se abaseteció a las 12 m/Tanqueta prestada
A19: 903 | B19: 45854 | D19: =+E16 -> 10449.4 | E19: 10459.1 | F19: =+E19-D19 -> 9.7 | G19: 0
A20: 904 | B20: 45855 | C20: 10460.3 | D20: =+E19 -> 10459.1 | E20: 10468.1 | F20: =+E20-D20 -> 9 | G20: 75 | I20: Faltaba llenar se abaseteció a las 8 am
A21: 905 | B21: 45856 | C21: 10471.1 | D21: =+E20 -> 10468.1 | E21: 10475.8 | F21: =+E21-D21 -> 7.7 | G21: 39.43 | I21: Faltaba llenar-maquinaria se descarilo se cambio uñas
A22: 906 | B22: 45857 | C22: 10477.8 | D22: =+E21 -> 10475.8 | E22: 10484 | F22: =+E22-D22 -> 8.2 | G22: 115 | I22: Faltaba llenar se abaseteció a las 10.30 am
A23: 907 | B23: 45858 | D23: =+E22 -> 10484 | E23: 10488.7 | F23: =+E23-D23 -> 4.7
A24: 908 | B24: 45859 | C24: 10494.1 | D24: =+E23 -> 10488.7 | E24: 10498 | F24: =+E24-D24 -> 9.3 | G24: 75.6 | I24: Tanque lleno
C25: =+C24-C16 -> 51.8 | G25: =SUM(G18:G24) -> 317.03 | H25: =+G25/C25 -> 6.1202703 | I25: CONTROL
A26: 909 | B26: 45860 | C26: 10505.1 | D26: =+E24 -> 10498 | E26: 10507.1 | F26: =+E26-D26 -> 9.1 | G26: 56
A27: 910 | B27: 45861 | D27: =+E26 -> 10507.1 | E27: 10517 | F27: =+E27-D27 -> 9.9
A28: 911 | B28: 45862 | C28: 10517 | D28: 10517 | E28: 10526.5 | F28: =+E28-D28 -> 9.5 | G28: 102.19
A29: 912 | B29: 45863 | C29: 10531.9 | D29: =+E28 -> 10526.5 | E29: 10536.7 | F29: =+E29-D29 -> 10.2 | G29: 101.07 | I29: Tanque lleno
C30: =+C29-C24 -> 37.8 | G30: =+G29+G28+G26 -> 259.26 | H30: =+G30/C30 -> 6.8587302 | I30: CONTROL
A31: 913 | B31: 45864 | D31: =+E29 -> 10536.7 | E31: 10542.6 | F31: =+E31-D31 -> 5.9
A32: 914 | B32: 45868 | C32: 10543.2 | D32: =+E31 -> 10542.6 | E32: 10550.8 | F32: =+E32-D32 -> 8.2 | G32: 81 | H32: =+G32/(C32-C29) -> 7.1681416 | I32: Tanque lleno
A33: 915 | B33: 45869 | D33: =+E32 -> 10550.8 | E33: 10560 | F33: =+E33-D33 -> 9.2
A34: 916 | B34: 45870 | D34: 10560 | E34: 10560 | F34: =+E34-D34 -> 0 | I34: Paró por falta de combustible
A35: 917 | B35: 45871 | C35: 10560 | D35: =+E33 -> 10560 | E35: 10570 | F35: =+E35-D35 -> 10 | G35: 104 | H35: =+G35/(C35-C32) -> 6.1904762 | I35: Tanque lleno
A36: 918 | B36: 45872 | D36: 10570 | E36: 10577.4 | F36: =+E36-D36 -> 7.4 | I36: Se rompió perno de la guia de cadena
A37: 919 | B37: 45873 | C37: 10577.8 | D37: 10577.4 | E37: 10586.8 | F37: =+E37-D37 -> 9.4 | G37: 110.95 | H37: =+G37/(C37-C35) -> 6.2331461 | I37: Tanque lleno
A38: 920 | B38: 45874 | C38: 10586.8 | D38: 10586.8 | E38: 10596.8 | F38: =+E38-D38 -> 10 | G38: 38.79 | I38: No lleno el tanque-se descarrilo cadena
A39: 921 | B39: 45875 | C39: 10599.9 | D39: 10596.8 | E39: 10599.9 | F39: =+E39-D39 -> 3.1 | G39: 81.415 | H39: =+G39/(C39-C38) -> 6.2148855 | I39: Tanque lleno/traslado a sector Pinto
A40: 922 | B40: 45876 | C40: 10599.9 | D40: 10599.9 | F40: =+E40-D40 -> -10599.9 | G40: -118 | I40: se le quito 118 galones para la doosan
C41: =+C39-C37 -> 22.1 | G41: =+G38+G39 -> 120.205 | H41: =+G41/C41 -> 5.4391403 | I41: CONTROL
A42: 923 | B42: 45878 | C42: 10601 | D42: 10599.9 | E42: 10603.6 | F42: =+E42-D42 -> 3.7 | G42: 37.44 | I42: No lleno tanque
...

Sheet TRAC D-155 82071
B2: CONTROL DE COMBUSTIBLE Y HORAS MAQUINA
A3: PROYECTO: | B3: SERVICIO DE ELABORACION DE FICHA TECNICA DEFINITIVA Y DESCOLMATACION POR EL ESTADO DE EMERGENCIA EN EL RIO VISCAZ-SECTOR VISCAZ, EN EL DISTRITO DE PLAPA PROVINCIA DE PALPA, DEPARTAMENTO DE ICA
A4: MAQUINARIA: | B4: TRACTOR KOMATSU D155- AX-6 SERIE 82071
A5: OPERADOR: | B5: GERARDO CASTILLO SANCHEZ
A6: UBICACIÓN: | B6: SECTOR VISCAZ | K6: =170-90 -> 80
A8: PARTE DIARIO | B8: FECHA | C8: HOROMETRO ABASTECIMIENTO | D8: HOROMETRO INICIAL | E8: HOROMETRO FINAL | F8: HORAS TRABAJADAS | G8: COMBUSTIBLE | H8: CONSUMO X HORA | I8: RENDIMIENTO Gal X Hr | J8: OBSERVACION
A9: 262 | B9: 45848 | C9: 15156 | D9: 15156 | E9: =+D10 -> 15161 | F9: =IF(D9="","",E9-D9) -> 5 | G9: 108.70297 | H9: =IF(G9="","",ROUND(G9/F9,2)) -> 21.74 | J9: TANQUE LLENO - llego de Huancayo
A10: 263 | B10: 45849 | D10: 15161 | E10: =+D11 -> 15169 | F10: =IF(D10="","",E10-D10) -> 8 | H10: =IF(G10="","",ROUND(G10/F10,2))
A11: 264 | B11: 45850 | C11: 15169 | D11: 15169 | E11: 15175 | F11: =IF(D11="","",E11-D11) -> 6 | G11: 90 | J11: Faltó para llenar el tanque | K11: =+C11-D11 -> 0
A12: 801 | B12: 45852 | C12: 15180 | D12: 15175 | E12: 15184 | F12: =IF(D12="","",E12-D12) -> 9 | G12: 90 | J12: Tanque lleno, abastecido cubo y surtidor, se perdió tiempo en el abstecimiento de combustible 30 min
C13: =+C12-C9 -> 24 | G13: =+G12+G11 -> 180 | I13: =+G13/C13 -> 7.5 | J13: CONTROL
A14: 803 | B14: 45853 | C14: 15186 | D14: =+E12 -> 15184 | E14: 15193 | F14: =IF(D14="","",E14-D14) -> 9 | G14: 114 | J14: Faltó para llenar el tanque
A15: 804 | B15: 45854 | D15: =+E14 -> 15193 | E15: 15203 | F15: =IF(D15="","",E15-D15) -> 10
A16: 805 | B16: 45855 | C16: 15204 | D16: =+E15 -> 15203 | E16: 15212 | F16: =IF(D16="","",E16-D16) -> 9 | G16: 90 | J16: Faltó para llenar el tanque
A17: 806 | B17: 45856 | C17: 15214 | D17: =+E16 -> 15212 | E17: 15221 | F17: =IF(D17="","",E17-D17) -> 9 | G17: 60.57 | J17: Faltó para llenar el tanque
A18: 807 | B18: 45857 | C18: 15223 | D18: =+E17 -> 15221 | E18: 15230 | F18: =IF(D18="","",E18-D18) -> 9 | G18: 105 | J18: Faltó para llenar el tanque
A19: 808 | B19: 45858 | D19: =+E18 -> 15230 | E19: 15236 | F19: =IF(D19="","",E19-D19) -> 6 | L19: =105+115 -> 220
A20: 809 | B20: 45859 | C20: 15239 | D20: =+E19 -> 15236 | E20: 15244 | F20: =IF(D20="","",E20-D20) -> 8 | G20: 109.81 | J20: Tanque lleno
C21: =+C20-C12 -> 59 | G21: =SUM(G14:H20) -> 479.38 | I21: =+G21/C21 -> 8.1250847 | J21: CONTROL
A22: 810 | B22: 45860 | C22: 15250 | D22: =+E20 -> 15244 | E22: 15253 | F22: =IF(D22="","",E22-D22) -> 9 | G22: 82.03 | I22: =+G22/(C22-C20) -> 7.4572727 | J22: Tanque lleno
A23: 811 | B23: 45861 | D23: =+E22 -> 15253 | E23: 15260 | F23: =IF(D23="","",E23-D23) -> 7
A24: 812 | B24: 45862 | C24: 15260 | D24: =+E23 -> 15260 | E24: 15270 | F24: =IF(D24="","",E24-D24) -> 10 | G24: 108.35 | J24: Tanque no llenó
A25: 813 | B25: 45863 | C25: 15275 | D25: =+E24 -> 15270 | E25: 15280 | F25: =IF(D25="","",E25-D25) -> 10 | G25: 123.83
A26: 814 | B26: 45864 | D26: =+E25 -> 15280 | E26: 15286 | F26: =IF(D26="","",E26-D26) -> 6
A27: 815 | B27: 45868 | C27: 15288 | D27: =+E26 -> 15286 | E27: 15293 | F27: =IF(D27="","",E27-D27) -> 7 | G27: 106.5 | J27: Tanque lleno
C28: =+C27-C22 -> 38 | F28: =IF(D28="","",E28-D28) | G28: =+G27+G25+G24 -> 338.68 | I28: =+G28/C28 -> 8.9126316 | J28: CONTROL
A29: 816 | B29: 45869 | D29: =+E27 -> 15293 | E29: 15303 | F29: =IF(D29="","",E29-D29) -> 10
B30: 45870 | D30: =+E29 -> 15303 | E30: =+D30 -> 15303 | F30: =IF(D30="","",E30-D30) -> 0
A31: 817 | B31: 45871 | C31: 15303 | D31: =+E29 -> 15303 | E31: 15309 | F31: =IF(D31="","",E31-D31) -> 6 | G31: 65 | J31: No lleno el tanque
B32: 45872
B33: 45883 | C33: 15377 | G33: 85 | J33: No lleno el tanque
B34: 45884 | C34: 15391 | G34: 109.72 | J34: No lleno el tanque
B35: 45885 | C35: 15408 | G35: 30 | J35: No lleno el tanque
B36: 45887 | C36: 15409 | G36: 87.13 | J36: No lleno el tanque
B37: 45888 | C37: 15416 | G37: 92.63 | J37: No lleno el tanque
B38: 45889 | C38: 15429 | G38: 121.83 | J38: No lleno el tanque
B39: 45890 | C39: 15434 | G39: 51.47
B40: 45891 | C40: 15445 | G40: 77
B41: 45892 | C41: 15455 | G41: 92.27
B42: 45894 | C42: 15459 | G42: 61.23 | J42: Tanque lleno
...

Sheet TRAC-D155 82081
B2: CONTROL DE COMBUSTIBLE Y HORAS MAQUINA
A3: PROYECTO: | B3: SERVICIO DE ELABORACION DE FICHA TECNICA DEFINITIVA Y DESCOLMATACION POR EL ESTADO DE EMERGENCIA EN EL RIO GRANDE-SECTOR PINTO, EN EL DISTRITO DE RIO GRANDE, PROVINCIA DE PALPA, DEPARTAMENTO DE ICA
A4: MAQUINARIA: | B4: TRACTOR KOMATSU D155- AX-6 SERIE 82081
A5: OPERADOR: | B5: DAVID NUÑEZ VILCA
B6: Juan Jose Garcia Ore
A7: UBICACIÓN: | B7: CENTRO POBLADO DE VISCAZ-SECTOR PINTO
A9: PARTE DIARIO | B9: FECHA | C9: HOROMETRO ABASTECIMIENTO | D9: HOROMETRO INICIAL | E9: HOROMETRO FINAL | F9: HORAS TRABAJADAS | G9: COMBUSTIBLE | H9: RENDIMIENTO Gal X Hr | I9: OBSERVACION
A10: 257 | B10: 45845 | C10: 15075 | D10: 15075 | E10: 15083 | F10: =IF(D10="","",E10-D10) -> 8 | G10: 0 | I10: Ingresó con tanque lleno
A11: 259 | B11: 45846 | C11: 15088 | D11: =+E10 -> 15083 | E11: 15091 | F11: =IF(D11="","",E11-D11) -> 8 | G11: 75.94 | I11: Faltó para llenar
A12: 260 | B12: 45847 | C12: 15096 | D12: =+E11 -> 15091 | E12: 15100 | F12: =IF(D12="","",E12-D12) -> 9 | G12: 75.1 | I12: Faltó para llenar
A13: 261 | B13: 45848 | C13: 15107 | D13: =+E12 -> 15100 | E13: 15107 | F13: =IF(D13="","",E13-D13) -> 7 | G13: 79.55021 | I13: Se cambió de maquinaria por un tema de cuchilla autorizó Wilmer Sarmiento, pasó a sector Pinto(se abastecio en grifo) tanque lleno
B14: 45849 | C14: 15111 | D14: =+E13 -> 15107 | E14: 15111 | F14: =IF(D14="","",E14-D14) -> 4 | G14: 36 | I14: Inicia el nuevo operador David Nuñez Vilca 2pm
B15: 45850 | D15: 15111 | E15: 15117 | F15: =IF(D15="","",E15-D15) -> 6
A16: 660 | B16: 45852 | C16: 15125 | D16: =+E15 -> 15117 | E16: 15125 | F16: =IF(D16="","",E16-D16) -> 8 | G16: 109.7317 | I16: Tanque lleno a las 5:20 pm
C17: =+C16-C10 -> 50 | G17: =SUM(G11:G16) -> 376.32191 | H17: =+G17/C17 -> 7.5264382 | I17: CONTROL
A18: 688 | B18: 45853 | C18: 15136 | D18: 15125 | E18: 15136 | F18: =IF(D18="","",E18-D18) -> 11 | G18: 30 | H18: =+G18/(C18-C16) -> 2.7272727 | I18: Faltó para llenar
A19: 642 | B19: 45854 | C19: 15136 | D19: =+E18 -> 15136 | E19: 15140 | F19: =IF(D19="","",E19-D19) -> 4 | G19: 85.7 | H19: =+G19/(C19-C16) -> 7.7909091 | I19: Faltó para llenar
A20: 655 | B20: 45855 | D20: 15140 | E20: 15150 | F20: =IF(D20="","",E20-D20) -> 10
A21: 401 | B21: 45856 | C21: 15154 | D21: =+E20 -> 15150 | E21: 15157 | F21: =IF(D21="","",E21-D21) -> 7 | G21: 39.89 | I21: Faltó para llenar/aceite de motor a las 6am
A22: 403 | B22: 45857 | C22: 15157 | D22: =+E21 -> 15157 | E22: 15165 | F22: =IF(D22="","",E22-D22) -> 8 | G22: 104
A23: 404 | B23: 45859 | C23: 15170 | D23: =+E22 -> 15165 | E23: 15171 | F23: =IF(D23="","",E23-D23) -> 6 | G23: 67.91 | I23: Tanque lleno 11 am/ maquina averiada
C24: =+C23-C16 -> 45 | F24: =IF(D24="","",E24-D24) | G24: =SUM(G18:G23) -> 327.5 | H24: =+G24/C24 -> 7.2777778 | I24: CONTROL
B25: 45860 | D25: =+E23 -> 15171 | E25: =+D25 -> 15171 | F25: =IF(D25="","",E25-D25) -> 0
F26: =IF(D26="","",E26-D26)
B27: 45869 | D27: =+E25 -> 15171 | E27: 15178 | F27: =IF(D27="","",E27-D27) -> 7 | I27: Operador nuevo Luis Zevallos Andray/turno noche
A28: 412 | B28: 45870 | D28: =+E27 -> 15178 | E28: 15182 | F28: =IF(D28="","",E28-D28) -> 4 | I28: Aceite de motor 1/4 gln/operador David
A29: 413 | B29: 45871 | C29: 15182 | D29: =+E28 -> 15182 | E29: 15189 | F29: =IF(D29="","",E29-D29) -> 7 | G29: 125.5 | I29: Operador David Nuñez vilca
B30: 45871 | D30: =+E29 -> 15189 | E30: 15196 | F30: =IF(D30="","",E30-D30) -> 7 | I30: Operador nuevo Luis Zevallos Andray/turno noche
B31: 45872 | C31: 15196 | D31: =+E30 -> 15196 | E31: =+D31+8 -> 15204 | F31: =IF(D31="","",E31-D31) -> 8 | G31: 117.41 | I31: Operador David Nuñez vilca
B32: 45873 | C32: 15210 | F32: =+E32-D32 -> 0 | G32: 105.7 | I32: Tanque lleno
C33: =+C32-C23 -> 40 | G33: =+G32+G31+G29 -> 348.61 | H33: =+G33/C33 -> 8.71525 | I33: CONTROL
B34: 45874 | C34: 15222 | F34: =+E34-D34 -> 0 | G34: 122 | I34: falta llenar
B35: 45875 | C35: 15237 | F35: =+E35-D35 -> 0 | G35: 108.26 | H35: =+G35/(C35-C34) -> 7.2173333 | I35: Tanque lleno
A36: 614 | B36: 45876 | D36: 15246 | E36: 15254 | F36: =+E36-D36 -> 8 | I36: Operador Ferreira
A37: 418 | B37: 45876 | C37: 15250 | D37: 15254 | E37: 15262 | F37: =+E37-D37 -> 8 | G37: 102.68 | H37: =+G37/(C37-C35) -> 7.8984615 | I37: Tanque lleno-Operador David turno noche
A38: 615 | B38: 45877 | C38: 15265 | D38: 15262 | E38: 15271 | F38: =+E38-D38 -> 9 | G38: 71.4 | I38: Abastecimiento interno dekomatsu I/falta llenar
A39: 419 | B39: 45877 | D39: 15271 | E39: 15272 | F39: =+E39-D39 -> 1 | I39: Operador David Nuñez vilca-paralizó por falta de comb.
A40: 616 | B40: 45878 | C40: 15273 | D40: 15272 | E40: 15279 | F40: =+E40-D40 -> 7 | G40: 113.86 | I40: Tanque lleno/operador Ferreira
A41: 420 | B41: 45878 | D41: 15279 | E41: 15287 | F41: =+E41-D41 -> 8 | I41: Operador David Nuñez vilca
C42: =+C40-C35 -> 36 | G42: =+G40+G38+G37 -> 287.94 | H42: =+G42/C42 -> 7.9983333 | I42: CONTROL
...

Sheet TRAC D-komatsu
B2: CONTROL DE COMBUSTIBLE Y HORAS MAQUINA
A3: PROYECTO: | B3: SERVICIO DE ELABORACION DE FICHA TECNICA DEFINITIVA Y DESCOLMATACION POR EL ESTADO DE EMERGENCIA EN EL RIO GRANDE-SECTOR PINTO, EN EL DISTRITO DE RIO GRANDE, PROVINCIA DE PALPA, DEPARTAMENTO DE ICA
A4: MAQUINARIA: | B4: TRACTOR KOMATSU D155- AX-6 SERIE 81559
A5: OPERADOR: | B5: CESAR CALDERON | K5: =+K6*2 -> 34.52
B6: LUCIO FLORES FLORES | K6: =51.78/3 -> 17.26
A7: UBICACIÓN: | B7: DISTRITO DE RIO GRANDE | K7: =52-G13 -> -52
A9: PARTE DIARIO | B9: FECHA | C9: HOROMETRO ABASTECIMIENTO | D9: HOROMETRO INICIAL | E9: HOROMETRO FINAL | F9: HORAS TRABAJADAS | G9: COMBUSTIBLE | H9: CONSUMO X HORA | I9: RENDIMIENTO Gal X Hr | J9: OBSERVACION
B10: 45845 | C10: 11652 | D10: 11652 | E10: 11654 | F10: =IF(D10="","",E10-D10) -> 2 | H10: =IF(G10="","",ROUND(G10/F10,2)) | J10: TANQUE LLENO
B11: 45846 | D11: =+E10 -> 11654 | E11: 11664 | F11: =IF(D11="","",E11-D11) -> 10 | H11: =IF(G11="","",ROUND(G11/F11,2)) | I11: =+G11/(C11-C10) -> 0
B12: 45847 | D12: =+E11 -> 11664 | E12: 11674 | F12: =IF(D12="","",E12-D12) -> 10 | K12: =+C12-D12 -> -11664
B13: 45848 | C13: 11674 | D13: 11674 | E13: 11684 | F13: =+E13-D13 -> 10 | G13: 104 | J13: Falta llenar se abasecio en dos viajes en bidones de 52 gln
B14: 45849 | C14: 11679 | D14: 11684 | E14: 11691 | F14: =+E14-D14 -> 7 | G14: 34.52 | J14: Falta llenar/se abasteció en bidones
B15: 45850 | J15: NO LABORO POR AVERIAS
A16: 689 | B16: 45852 | C16: =+E14 -> 11691 | D16: =+E14 -> 11691 | E16: 11695 | F16: =+E16-D16 -> 4 | G16: 106.33331 | J16: Falta llenar/se abastecion en cilindroy bidones
A17: 691 | B17: 45853 | C17: 11701 | D17: =+E16 -> 11695 | E17: 11704 | F17: =+E17-D17 -> 9 | G17: 120 | J17: TANQUE LLENO
C18: =+C17-C10 -> 49 | G18: =+G17+G16+G14+G13 -> 364.85331 | I18: =+G18/C18 -> 7.4459859 | J18: CONTROL
A19: 669 | B19: 45854 | D19: =+E17 -> 11704 | E19: 11709 | F19: =+E19-D19 -> 5
A20: 654 | B20: 45855 | D20: =+E19 -> 11709 | E20: 11717 | F20: =+E20-D20 -> 8
A21: 601 | B21: 45856 | C21: 11717 | D21: =+E20 -> 11717 | E21: 11717 | F21: =+E21-D21 -> 0 | G21: 40.122 | J21: Maquinaria en reparacion/lubricantes1gl aceite de motor
A22: 605 | B22: 45857 | D22: =+E21 -> 11717 | E22: 11721 | F22: =+E22-D22 -> 4
A23: 606 | B23: 45859 | C23: 11723 | D23: =+E22 -> 11721 | E23: 11726 | F23: =+E23-D23 -> 5 | G23: 127.46 | J23: TANQUE LLENO
C24: =+C23-C17 -> 22 | F24: =+E24-D24 -> 0 | G24: =SUM(G19:G23) -> 167.582 | I24: =+G24/C24 -> 7.6173636 | J24: CONTROL
A25: 607 | B25: 45860 | C25: 11732 | D25: =+E23 -> 11726 | E25: 11731 | F25: =+E25-D25 -> 5 | G25: 70 | I25: =+G25/(C25-C23) -> 7.7777778 | J25: TANQUE LLENO | K25: 352.63
A26: 405 | B26: 45860 | D26: =+E25 -> 11731 | E26: 11738 | F26: =+E26-D26 -> 7 | J26: Turno noche/David
A27: 608 | B27: 45861 | C27: 11745 | D27: =+E26 -> 11738 | E27: 11746 | F27: =+E27-D27 -> 8 | G27: 89 | J27: Turno diurno Lucio | K27: 3.7854118 | L27: LITROS POR GALON
A28: 406 | B28: 45861 | D28: =+E27 -> 11746 | E28: 11753 | F28: =+E28-D28 -> 7 | J28: Turno noche/David
A29: 609 | B29: 45862 | C29: 11758 | D29: =+E28 -> 11753 | E29: 11762 | F29: =+E29-D29 -> 9 | G29: 107.92 | K29: =+K25/K27 -> 93.154991
A30: 407 | B30: 45862 | D30: =+E29 -> 11762 | E30: 11769 | F30: =+E30-D30 -> 7 | J30: Turno noche/David
A31: 610 | B31: 45863 | C31: 11773 | D31: =+E30 -> 11769 | E31: 11776 | F31: =+E31-D31 -> 7 | G31: 111.23 | J31: TANQUE LLENO
A32: 408 | B32: 45863 | D32: =+E31 -> 11776 | E32: 11784 | F32: =+E32-D32 -> 8
C33: =+C31-C25 -> 41 | G33: =+G31+G29+G27 -> 308.15 | I33: =+G33/C33 -> 7.5158537 | J33: CONTROL
A34: 409 | B34: 45864 | C34: 11784 | D34: =+E32 -> 11784 | E34: 11794 | F34: =+E34-D34 -> 10 | G34: 93.16 | I34: =+G34/(C34-C31) -> 8.4690909 | J34: FALTA LLENAR
A35: 410 | B35: 45868 | C35: 11797 | D35: =+E34 -> 11794 | E35: 11799 | F35: =+E35-D35 -> 5 | G35: 103.4 | I35: =+G35/(C35-C34) -> 7.9538462 | J35: Operador David
A36: 411 | B36: 45869 | D36: =+E35 -> 11799 | E36: 11807 | F36: =+E36-D36 -> 8 | J36: Operador David
B37: 45870 | D37: =+E36 -> 11807 | E37: 11810 | F37: =+E37-D37 -> 3
A38: 712 | B38: 45871 | C38: 11810 | D38: =+E37 -> 11810 | E38: 11817 | F38: =+E38-D38 -> 7 | G38: 108.8 | I38: =+G38/(C38-C35) -> 8.3692308 | J38: Nuevo operador Raul Ferreyra no lleno el tanque
A39: 611 | B39: 45872 | C39: 11817 | D39: =+E38 -> 11817 | E39: 11819 | F39: =+E39-D39 -> 2 | G39: 47.59 | I39: =+G39/(C39-C38) -> 6.7985714 | J39: Nuevo operador Raul Ferreyra no lleno el tanque
J40: Maquinaria con averias en evaluacion y mantenimiento
B41: 45877 | C41: 11819 | G41: -71.4 | J41: Se extrajo para abastecimiento interno
A46: Total | F46: =SUM(F10:F45) -> 167 | G46: =SUM(G10:G45) -> 2032.7206 | H46: =IF(G46="","",ROUND(G46/F46,2)) -> 12.17 | J46: Consumo promedio de equipo pesado acumulado
...

Sheet Consolidado
A2: RESUMEN DE CONTROL DE COMBUSTIBLE
A4: MAQUINARIA: | B4: TODAS
A5: UBICACIÓN:
A6: Elaborado
A7: ITEM | B7: EQUIPO PESADO | D7: CONSUMO DIARIOS EN GALONES DE PETROLEO POR MAQUINA SECTOR VISCAZ | BU7: TOTAL COMBUSTIBLE
C8: ANTERIOR | D8: 45845 | E8: 45846 | F8: 45847 | G8: 45848 | H8: 45849 | I8: 45850 | J8: 45852 | K8: 45853 | L8: 45854 | M8: 45855 | N8: 45856 | O8: 45857 | Q8: 45859 | R8: 45860 | S8: 45861 | T8: 45862 | U8: 45863 | V8: 45864 | W8: 45868 | X8: 45869 | Y8: 45870 | Z8: 45871 | AA8: 45872 | AB8: 45873 | AC8: 45874 | AD8: 45875 | AE8: 45876 | AF8: 45877 | AG8: 45878 | AH8: 45879 | AI8: 45880 | AJ8: 45881 | AK8: 45882 | AL8: 45883 | AM8: 45884 | AN8: 45885 | AO8: 45886 | AP8: 45887 | AQ8: 45888 | AR8: 45889 | AS8: 45890 | AT8: 45891 | AU8: 45892 | AV8: 45893 | AW8: 45894 | AX8: 45895 | AY8: 45896 | AZ8: 45897 | BA8: 45898 | BB8: 45899
A10: 1 | B10: EXCAVADORA KOBELCO SK 350 | D10: =SUMIF('EXC. Kobelco SK-350'!$B$9:$B$76,Consolidado!D8,'EXC. Kobelco SK-350'!$G$9:$G$76) -> 0 | E10: =SUMIF('EXC. Kobelco SK-350'!$B$9:$B$76,Consolidado!E8,'EXC. Kobelco SK-350'!$G$9:$G$76) -> 79.06 | F10: =SUMIF('EXC. Kobelco SK-350'!$B$9:$B$76,Consolidado!F8,'EXC. Kobelco SK-350'!$G$9:$G$76) -> 39.9 | G10: =SUMIF('EXC. Kobelco SK-350'!$B$9:$B$76,Consolidado!G8,'EXC. Kobelco SK-350'!$G$9:$G$76) -> 0 | H10: =SUMIF('EXC. Kobelco SK-350'!$B$9:$B$76,Consolidado!H8,'EXC. Kobelco SK-350'!$G$9:$G$76) -> 70 | I10: =SUMIF('EXC. Kobelco SK-350'!$B$9:$B$76,Consolidado!I8,'EXC. Kobelco SK-350'!$G$9:$G$76) -> 90 | J10: =SUMIF('EXC. Kobelco SK-350'!$B$9:$B$76,Consolidado!J8,'EXC. Kobelco SK-350'!$G$9:$G$76) -> 80 | K10: =SUMIF('EXC. Kobelco SK-350'!$B$9:$B$76,Consolidado!K8,'EXC. Kobelco SK-350'!$G$9:$G$76) -> 82 | ... O10: =SUMIF('EXC. Kobelco SK-350'!$B$9:$B$76,Consolidado!O8,'EXC. Kobelco SK-350'!$G$9:$G$76) -> 115 | Q10: =SUMIF('EXC. Kobelco SK-350'!$B$9:$B$76,Consolidado!Q8,'EXC. Kobelco SK-350'!$G$9:$G$76) -> 75.6 | R10: =SUMIF('EXC. Kobelco SK-350'!$B$9:$B$76,Consolidado!R8,'EXC. Kobelco SK-350'!$G$9:$G$76) -> 56 | S10: =SUMIF('EXC. Kobelco SK-350'!$B$9:$B$76,Consolidado!S8,'EXC. Kobelco SK-350'!$G$9:$G$76) -> 0 | T10: =SUMIF('EXC. Kobelco SK-350'!$B$9:$B$76,Consolidado!T8,'EXC. Kobelco SK-350'!$G$9:$G$76) -> 102.19 | U10: =SUMIF('EXC. Kobelco SK-350'!$B$9:$B$76,Consolidado!U8,'EXC. Kobelco SK-350'!$G$9:$G$76) -> 101.07 | V10: =SUMIF('EXC. Kobelco SK-350'!$B$9:$B$76,Consolidado!V8,'EXC. Kobelco SK-350'!$G$9:$G$76) -> 0 | W10: =SUMIF('EXC. Kobelco SK-350'!$B$9:$B$76,Consolidado!W8,'EXC. Kobelco SK-350'!$G$9:$G$76) -> 81 | X10: =SUMIF('EXC. Kobelco SK-350'!$B$9:$B$76,Consolidado!X8,'EXC. Kobelco SK-350'!$G$9:$G$76) -> 0 | ... AC10: =SUMIF('EXC. Kobelco SK-350'!$B$9:$B$76,Consolidado!AC8,'EXC. Kobelco SK-350'!$G$9:$G$76) -> 38.79 | BU10: =SUM(C10:BB10) -> 1339.99
A11: 2 | B11: TRACTOR D155 - AX 82081 | D11: =SUMIF('TRAC-D155 82081'!$B$10:$B$85,Consolidado!D$8,'TRAC-D155 82081'!$G$10:$G$85) -> 0 | E11: =SUMIF('TRAC-D155 82081'!$B$10:$B$85,Consolidado!E$8,'TRAC-D155 82081'!$G$10:$G$85) -> 75.94 | F11: =SUMIF('TRAC-D155 82081'!$B$10:$B$85,Consolidado!F$8,'TRAC-D155 82081'!$G$10:$G$85) -> 75.1 | R11: =SUMIF('TRAC-D155 82081'!$B$10:$B$85,Consolidado!R8,'TRAC-D155 82081'!$G$10:$G$85) -> 0 | S11: =SUMIF('TRAC-D155 82081'!$B$10:$B$85,Consolidado!S8,'TRAC-D155 82081'!$G$10:$G$85) -> 0 | T11: =SUMIF('TRAC-D155 82081'!$B$10:$B$85,Consolidado!T8,'TRAC-D155 82081'!$G$10:$G$85) -> 0 | U11: =SUMIF('TRAC-D155 82081'!$B$10:$B$85,Consolidado!U8,'TRAC-D155 82081'!$G$10:$G$85) -> 0 | V11: =SUMIF('TRAC-D155 82081'!$B$10:$B$85,Consolidado!V8,'TRAC-D155 82081'!$G$10:$G$85) -> 0 | W11: =SUMIF('TRAC-D155 82081'!$B$10:$B$85,Consolidado!W8,'TRAC-D155 82081'!$G$10:$G$85) -> 0 | X11: =SUMIF('TRAC-D155 82081'!$B$10:$B$85,Consolidado!X8,'TRAC-D155 82081'!$G$10:$G$85) -> 0 | Y11: =SUMIF('TRAC-D155 82081'!$B$10:$B$85,Consolidado!Y8,'TRAC-D155 82081'!$G$10:$G$85) -> 0 | BU11: =SUM(C11:BB11) -> 151.04
A12: 3 | B12: TRACTOR D155 - AX 82071 | C12: =+'TRAC D-155 82071'!G9 -> 108.70297 | D12: =SUMIF('TRAC D-155 82071'!$B$9:$B$59,Consolidado!D$8,'TRAC D-155 82071'!$G$9:$G$68) -> 0 | E12: =SUMIF('TRAC D-155 82071'!$B$9:$B$59,Consolidado!E$8,'TRAC D-155 82071'!$G$9:$G$68) -> 0 | F12: =SUMIF('TRAC D-155 82071'!$B$9:$B$59,Consolidado!F$8,'TRAC D-155 82071'!$G$9:$G$68) -> 0 | G12: =SUMIF('TRAC D-155 82071'!$B$9:$B$59,Consolidado!G$8,'TRAC D-155 82071'!$G$9:$G$68) -> 108.70297 | H12: =SUMIF('TRAC D-155 82071'!$B$9:$B$59,Consolidado!H$8,'TRAC D-155 82071'!$G$9:$G$68) -> 0 | I12: =SUMIF('TRAC D-155 82071'!$B$9:$B$59,Consolidado!I$8,'TRAC D-155 82071'!$G$9:$G$68) -> 90 | J12: =SUMIF('TRAC D-155 82071'!$B$9:$B$59,Consolidado!J$8,'TRAC D-155 82071'!$G$9:$G$68) -> 90 | K12: =SUMIF('TRAC D-155 82071'!$B$9:$B$59,Consolidado!K$8,'TRAC D-155 82071'!$G$9:$G$68) -> 114 | ... O12: =SUMIF('TRAC D-155 82071'!$B$9:$B$59,Consolidado!O$8,'TRAC D-155 82071'!$G$9:$G$68) -> 105 | Q12: =SUMIF('TRAC D-155 82071'!$B$9:$B$59,Consolidado!Q$8,'TRAC D-155 82071'!$G$9:$G$68) -> 109.81 | R12: =SUMIF('TRAC D-155 82071'!$B$9:$B$59,Consolidado!R$8,'TRAC D-155 82071'!$G$9:$G$68) -> 82.03 | S12: =SUMIF('TRAC D-155 82071'!$B$9:$B$59,Consolidado!S$8,'TRAC D-155 82071'!$G$9:$G$68) -> 0 | T12: =SUMIF('TRAC D-155 82071'!$B$9:$B$59,Consolidado!T$8,'TRAC D-155 82071'!$G$9:$G$68) -> 108.35 | U12: =SUMIF('TRAC D-155 82071'!$B$9:$B$59,Consolidado!U$8,'TRAC D-155 82071'!$G$9:$G$68) -> 123.83 | V12: =SUMIF('TRAC D-155 82071'!$B$9:$B$59,Consolidado!V$8,'TRAC D-155 82071'!$G$9:$G$68) -> 0 | W12: =SUMIF('TRAC D-155 82071'!$B$9:$B$59,Consolidado!W$8,'TRAC D-155 82071'!$G$9:$G$68) -> 106.5 | X12: =SUMIF('TRAC D-155 82071'!$B$9:$B$59,Consolidado!X$8,'TRAC D-155 82071'!$G$9:$G$68) -> 0 | ... AC12: =SUMIF('TRAC D-155 82071'!$B$9:$B$59,Consolidado!AC$8,'TRAC D-155 82071'!$G$9:$G$68) -> 0 | BU12: =SUM(C12:BB12) -> 1362.4959
A13: 4 | B13: CAMIONETA DE SERVICIO | E13: =SUMIF('Camioneta serv'!$B$9:$B$15,Consolidado!E$8,'Camioneta serv'!$G$9:$G$15) -> 5 | F13: =SUMIF('Camioneta serv'!$B$9:$B$15,Consolidado!F$8,'Camioneta serv'!$G$9:$G$15) -> 0 | I13: =SUMIF('Camioneta serv'!$B$9:$B$15,Consolidado!I$8,'Camioneta serv'!$G$9:$G$15) -> 5 | J13: =SUMIF('Camioneta serv'!$B$9:$B$15,Consolidado!J$8,'Camioneta serv'!$G$9:$G$15) -> 5 | K13: =SUMIF('Camioneta serv'!$B$9:$B$15,Consolidado!K$8,'Camioneta serv'!$G$9:$G$15) -> 4 | L13: =SUMIF('Camioneta serv'!$B$9:$B$15,Consolidado!L$8,'Camioneta serv'!$G$9:$G$15) -> 0 | M13: =SUMIF('Camioneta serv'!$B$9:$B$15,Consolidado!M$8,'Camioneta serv'!$G$9:$G$15) -> 5 | N13: =SUMIF('Camioneta serv'!$B$9:$B$18,Consolidado!N$8,'Camioneta serv'!$G$9:$G$18) -> 0 | O13: =SUMIF('Camioneta serv'!$B$9:$B$18,Consolidado!O$8,'Camioneta serv'!$G$9:$G$18) -> 0 | Q13: =SUMIF('Camioneta serv'!$B$9:$B$18,Consolidado!Q$8,'Camioneta serv'!$G$9:$G$18) -> 0 | R13: =SUMIF('Camioneta serv'!$B$9:$B$18,Consolidado!R$8,'Camioneta serv'!$G$9:$G$18) -> 0 | S13: =SUMIF('Camioneta serv'!$B$9:$B$18,Consolidado!S$8,'Camioneta serv'!$G$9:$G$18) -> 0 | T13: =SUMIF('Camioneta serv'!$B$9:$B$18,Consolidado!T$8,'Camioneta serv'!$G$9:$G$18) -> 0 | U13: =SUMIF('Camioneta serv'!$B$9:$B$18,Consolidado!U$8,'Camioneta serv'!$G$9:$G$18) -> 0 | V13: =SUMIF('Camioneta serv'!$B$9:$B$18,Consolidado!V$8,'Camioneta serv'!$G$9:$G$18) -> 0 | W13: =SUMIF('Camioneta serv'!$B$9:$B$18,Consolidado!W$8,'Camioneta serv'!$G$9:$G$18) -> 0 | X13: =SUMIF('Camioneta serv'!$B$9:$B$18,Consolidado!X$8,'Camioneta serv'!$G$9:$G$18) -> 0 | ... AK13: =SUMIF('Camioneta serv'!$B$9:$B$18,Consolidado!AK$8,'Camioneta serv'!$G$9:$G$18) -> 0 | AL13: 18.86 | AM13: =SUMIF('Camioneta serv'!$B$9:$B$18,Consolidado!AM$8,'Camioneta serv'!$G$9:$G$18) -> 0 | AN13: =SUMIF('Camioneta serv'!$B$9:$B$18,Consolidado!AN$8,'Camioneta serv'!$G$9:$G$18) -> 0 | AO13: =SUMIF('Camioneta serv'!$B$9:$B$18,Consolidado!AO$8,'Camioneta serv'!$G$9:$G$18) -> 0 | AP13: =SUMIF('Camioneta serv'!$B$9:$B$18,Consolidado!AP$8,'Camioneta serv'!$G$9:$G$18) -> 0 | AQ13: =SUMIF('Camioneta serv'!$B$9:$B$18,Consolidado!AQ$8,'Camioneta serv'!$G$9:$G$18) -> 0 | AR13: =SUMIF('Camioneta serv'!$B$9:$B$18,Consolidado!AR$8,'Camioneta serv'!$G$9:$G$18) -> 0 | AS13: =SUMIF('Camioneta serv'!$B$9:$B$18,Consolidado!AS$8,'Camioneta serv'!$G$9:$G$18) -> 0 | BU13: =SUM(C13:BB13) -> 47.86
A14: TOTAL | C14: =SUM(C10:C12) -> 108.70297 | D14: =SUM(D10:D12) -> 0 | E14: =SUM(E10:E13) -> 160 | F14: =SUM(F10:F13) -> 115 | G14: =SUM(G10:G13) -> 108.70297 | H14: =SUM(H10:H13) -> 70 | I14: =SUM(I10:I13) -> 185 | J14: =SUM(J10:J13) -> 175 | K14: =SUM(K10:K13) -> 200 | L14: =SUM(L10:L13) -> 0 | ... O14: =SUM(O10:O13) -> 220 | Q14: =SUM(Q10:Q13) -> 185.41 | R14: =SUM(R10:R13) -> 138.03 | S14: =SUM(S10:S13) -> 0 | T14: =SUM(T10:T13) -> 210.54 | U14: =SUM(U10:U13) -> 224.9 | V14: =SUM(V10:V13) -> 0 | W14: =SUM(W10:W13) -> 187.5 | X14: =SUM(X10:X13) -> 0 | ... AT14: =SUM(AT10:AT13) -> 0 | BA14: =SUM(BA10:BA13) -> 0 | BB14: =SUM(BB10:BB13) -> 0 | BU14: =SUM(BU10:BU13) -> 2901.3859
A17: ITEM | B17: EQUIPO PESADO | D17: CONSUMO DIARIOS EN GALONES DE PETROLEO POR MAQUINA SECTOR PINTO | BU17: TOTAL COMBUSTIBLE
C18: ANTERIOR | D18: 45845 | E18: 45846 | F18: 45847 | G18: 45848 | H18: 45849 | I18: 45850 | J18: 45852 | K18: 45853 | L18: 45854 | M18: 45855 | N18: 45856 | O18: 45857 | Q18: 45859 | R18: 45860 | S18: 45861 | T18: 45862 | U18: 45863 | V18: 45864 | W18: 45868 | X18: 45869 | Y18: 45870 | Z18: 45871 | AA18: 45872 | AB18: 45873 | AC18: 45874 | AD18: 45875 | AE18: 45876 | AF18: 45877 | AG18: 45878 | AH18: 45879 | AI18: 45880 | AJ18: 45881 | AK18: 45882 | AL18: 45883 | AM18: 45884 | AN18: 45885 | AO18: 45886 | AP18: 45887 | AQ18: 45888 | AR18: 45889 | AS18: 45890 | AT18: 45891 | AU18: 45892 | AV18: 45893 | AW18: 45894 | AX18: 45895 | AY18: 45896 | AZ18: 45897 | BA18: 45898 | BB18: 45899 | BC18: 45900 | BD18: 45901 | BE18: 45902 | BF18: 45903 | BG18: 45904 | BH18: 45905 | BI18: 45906 | BJ18: 45907 | BK18: 45908 | BL18: 45909 | BM18: 45910 | BN18: 45911 | BO18: 45912 | BP18: 45913 | BQ18: 45914 | BR18: 45915 | BS18: 45916 | BT18: 45923
A20: 1 | B20: EXCAVADORA KOBELCO SK 350 | AD20: =SUMIF('EXC. Kobelco SK-350'!$B$9:$B$76,Consolidado!AD18,'EXC. Kobelco SK-350'!$G$9:$G$76) -> 81.415 | AE20: =SUMIF('EXC. Kobelco SK-350'!$B$9:$B$76,Consolidado!AE18,'EXC. Kobelco SK-350'!$G$9:$G$76) -> -118 | AF20: =SUMIF('EXC. Kobelco SK-350'!$B$9:$B$76,Consolidado!AF18,'EXC. Kobelco SK-350'!$G$9:$G$76) -> 0 | AG20: =SUMIF('EXC. Kobelco SK-350'!$B$9:$B$76,Consolidado!AG18,'EXC. Kobelco SK-350'!$G$9:$G$76) -> 37.44 | AH20: =SUMIF('EXC. Kobelco SK-350'!$B$9:$B$76,Consolidado!AH18,'EXC. Kobelco SK-350'!$G$9:$G$76) -> 0 | AI20: =SUMIF('EXC. Kobelco SK-350'!$B$9:$B$76,Consolidado!AI18,'EXC. Kobelco SK-350'!$G$9:$G$76) -> 0 | AJ20: =SUMIF('EXC. Kobelco SK-350'!$B$9:$B$76,Consolidado!AJ18,'EXC. Kobelco SK-350'!$G$9:$G$76) -> 0 | AK20: =SUMIF('EXC. Kobelco SK-350'!$B$9:$B$76,Consolidado!AK18,'EXC. Kobelco SK-350'!$G$9:$G$76) -> 0 | ... BT20: =SUMIF('EXC. Kobelco SK-350'!$B$9:$B$76,Consolidado!BT18,'EXC. Kobelco SK-350'!$G$9:$G$76) -> 0 | BU20: =SUM(C20:BT20) -> 1550.175
A21: 2 | B21: EXCAVADORA DOOSAN | D21: =SUMIF('EXC. DOOSAN'!$B$10:$B$70,Consolidado!D18,'EXC. DOOSAN'!$G$10:$G$70) -> 0 | E21: =SUMIF('EXC. DOOSAN'!$B$10:$B$70,Consolidado!E18,'EXC. DOOSAN'!$G$10:$G$70) -> 0 | F21: =SUMIF('EXC. DOOSAN'!$B$10:$B$70,Consolidado!F18,'EXC. DOOSAN'!$G$10:$G$70) -> 0 | G21: =SUMIF('EXC. DOOSAN'!$B$10:$B$70,Consolidado!G18,'EXC. DOOSAN'!$G$10:$G$70) -> 17.26 | H21: =SUMIF('EXC. DOOSAN'!$B$10:$B$70,Consolidado!H18,'EXC. DOOSAN'!$G$10:$G$70) -> 108 | I21: =SUMIF('EXC. DOOSAN'!$B$10:$B$70,Consolidado!I18,'EXC. DOOSAN'!$G$10:$G$70) -> 0 | J21: =SUMIF('EXC. DOOSAN'!$B$10:$B$70,Consolidado!J18,'EXC. DOOSAN'!$G$10:$G$70) -> 157.267 | K21: =SUMIF('EXC. DOOSAN'!$B$10:$B$70,Consolidado!K18,'EXC. DOOSAN'!$G$10:$G$70) -> 0 | ... O21: =SUMIF('EXC. DOOSAN'!$B$10:$B$70,Consolidado!O18,'EXC. DOOSAN'!$G$10:$G$70) -> 76 | Q21: =SUMIF('EXC. DOOSAN'!$B$10:$B$70,Consolidado!Q18,'EXC. DOOSAN'!$G$10:$G$70) -> 81.8 | R21: =SUMIF('EXC. DOOSAN'!$B$10:$B$70,Consolidado!R18,'EXC. DOOSAN'!$G$10:$G$70) -> 83 | S21: =SUMIF('EXC. DOOSAN'!$B$10:$B$70,Consolidado!S18,'EXC. DOOSAN'!$G$10:$G$70) -> 76 | T21: =SUMIF('EXC. DOOSAN'!$B$10:$B$70,Consolidado!T18,'EXC. DOOSAN'!$G$10:$G$70) -> 0 | U21: =SUMIF('EXC. DOOSAN'!$B$10:$B$70,Consolidado!U18,'EXC. DOOSAN'!$G$10:$G$70) -> 95.46 | V21: =SUMIF('EXC. DOOSAN'!$B$10:$B$70,Consolidado!V18,'EXC. DOOSAN'!$G$10:$G$70) -> 62.48 | W21: =SUMIF('EXC. DOOSAN'!$B$10:$B$70,Consolidado!W18,'EXC. DOOSAN'!$G$10:$G$70) -> 86.3 | X21: =SUMIF('EXC. DOOSAN'!$B$10:$B$70,Consolidado!X18,'EXC. DOOSAN'!$G$10:$G$70) -> 0 | ... AH21: =SUMIF('EXC. DOOSAN'!$B$10:$B$70,Consolidado!AH18,'EXC. DOOSAN'!$G$10:$G$70) -> 0 | AQ21: =SUMIF('EXC. DOOSAN'!$B$10:$B$70,Consolidado!AQ18,'EXC. DOOSAN'!$G$10:$G$70) -> 0 | AR21: =SUMIF('EXC. DOOSAN'!$B$10:$B$70,Consolidado!AR18,'EXC. DOOSAN'!$G$10:$G$70) -> 0 | AS21: =SUMIF('EXC. DOOSAN'!$B$10:$B$70,Consolidado!AS18,'EXC. DOOSAN'!$G$10:$G$70) -> 0 | BB21: =SUMIF('EXC. DOOSAN'!$B$10:$B$70,Consolidado!BB18,'EXC. DOOSAN'!$G$10:$G$70) -> 0 | BU21: =SUM(C21:BT21) -> 1398.677
A22: 3 | B22: TRACTOR D155 - AX 82081 | D22: =SUMIF('TRAC-D155 82081'!$B$10:$B$85,Consolidado!D$8,'TRAC-D155 82081'!$G$10:$G$85) -> 0 | E22: 0 | F22: 0 | G22: =SUMIF('TRAC-D155 82081'!$B$10:$B$85,Consolidado!G$8,'TRAC-D155 82081'!$G$10:$G$85) -> 79.55021 | H22: =SUMIF('TRAC-D155 82081'!$B$10:$B$85,Consolidado!H$8,'TRAC-D155 82081'!$G$10:$G$85) -> 36 | I22: =SUMIF('TRAC-D155 82081'!$B$10:$B$85,Consolidado!I$8,'TRAC-D155 82081'!$G$10:$G$85) -> 0 | J22: =SUMIF('TRAC-D155 82081'!$B$10:$B$85,Consolidado!J$8,'TRAC-D155 82081'!$G$10:$G$85) -> 109.7317 | K22: =SUMIF('TRAC-D155 82081'!$B$10:$B$85,Consolidado!K18,'TRAC-D155 82081'!$G$10:$G$85) -> 30 | L22: =SUMIF('TRAC-D155 82081'!$B$10:$B$85,Consolidado!L18,'TRAC-D155 82081'!$G$10:$G$85) -> 85.7 | M22: =SUMIF('TRAC-D155 82081'!$B$10:$B$85,Consolidado!M18,'TRAC-D155 82081'!$G$10:$G$85) -> 0 | N22: =SUMIF('TRAC-D155 82081'!$B$10:$B$85,Consolidado!N18,'TRAC-D155 82081'!$G$10:$G$85) -> 39.89 | O22: =SUMIF('TRAC-D155 82081'!$B$10:$B$85,Consolidado!O18,'TRAC-D155 82081'!$G$10:$G$85) -> 104 | Q22: =SUMIF('TRAC-D155 82081'!$B$10:$B$85,Consolidado!Q18,'TRAC-D155 82081'!$G$10:$G$85) -> 67.91 | R22: =SUMIF('TRAC-D155 82081'!$B$10:$B$85,Consolidado!R18,'TRAC-D155 82081'!$G$10:$G$85) -> 0 | S22: =SUMIF('TRAC-D155 82081'!$B$10:$B$85,Consolidado!S18,'TRAC-D155 82081'!$G$10:$G$85) -> 0 | T22: =SUMIF('TRAC-D155 82081'!$B$10:$B$85,Consolidado!T18,'TRAC-D155 82081'!$G$10:$G$85) -> 0 | U22: =SUMIF('TRAC-D155 82081'!$B$10:$B$85,Consolidado!U18,'TRAC-D155 82081'!$G$10:$G$85) -> 0 | V22: =SUMIF('TRAC-D155 82081'!$B$10:$B$85,Consolidado!V18,'TRAC-D155 82081'!$G$10:$G$85) -> 0 | W22: =SUMIF('TRAC-D155 82081'!$B$10:$B$85,Consolidado!W18,'TRAC-D155 82081'!$G$10:$G$85) -> 0 | X22: =SUMIF('TRAC-D155 82081'!$B$10:$B$85,Consolidado!X18,'TRAC-D155 82081'!$G$10:$G$85) -> 0 | ... BT22: =SUMIF('TRAC-D155 82081'!$B$10:$B$85,Consolidado!BT18,'TRAC-D155 82081'!$G$10:$G$85) -> 0 | BU22: =SUM(C22:BT22) -> 4236.8619
A23: 4 | B23: TRACTOR D155 - AX 82071 | AH23: =SUMIF('TRAC D-155 82071'!$B$9:$B$59,Consolidado!AH$18,'TRAC D-155 82071'!$G$9:$G$68) -> 0 | AI23: =SUMIF('TRAC D-155 82071'!$B$9:$B$59,Consolidado!AI$18,'TRAC D-155 82071'!$G$9:$G$68) -> 0 | AJ23: =SUMIF('TRAC D-155 82071'!$B$9:$B$59,Consolidado!AJ$18,'TRAC D-155 82071'!$G$9:$G$68) -> 0 | AK23: =SUMIF('TRAC D-155 82071'!$B$9:$B$59,Consolidado!AK$18,'TRAC D-155 82071'!$G$9:$G$68) -> 0 | AL23: =SUMIF('TRAC D-155 82071'!$B$9:$B$59,Consolidado!AL$18,'TRAC D-155 82071'!$G$9:$G$68) -> 85 | AM23: =SUMIF('TRAC D-155 82071'!$B$9:$B$59,Consolidado!AM$18,'TRAC D-155 82071'!$G$9:$G$68) -> 109.72 | AN23: =SUMIF('TRAC D-155 82071'!$B$9:$B$59,Consolidado!AN$18,'TRAC D-155 82071'!$G$9:$G$68) -> 30 | AO23: =SUMIF('TRAC D-155 82071'!$B$9:$B$59,Consolidado!AO$18,'TRAC D-155 82071'!$G$9:$G$68) -> 0 | ... BH23: =SUMIF('TRAC D-155 82071'!$B$9:$B$59,Consolidado!BH$18,'TRAC D-155 82071'!$G$9:$G$68) -> 68.1088 | BI23: =SUMIF('TRAC D-155 82071'!$B$9:$B$68,Consolidado!BI$18,'TRAC D-155 82071'!$G$9:$G$68) -> 94.3 | BJ23: =SUMIF('TRAC D-155 82071'!$B$9:$B$68,Consolidado!BJ$18,'TRAC D-155 82071'!$G$9:$G$68) -> 79 | BK23: =SUMIF('TRAC D-155 82071'!$B$9:$B$68,Consolidado!BK$18,'TRAC D-155 82071'!$G$9:$G$68) -> 0 | BL23: =SUMIF('TRAC D-155 82071'!$B$9:$B$68,Consolidado!BL$18,'TRAC D-155 82071'!$G$9:$G$68) -> 93 | BM23: =SUMIF('TRAC D-155 82071'!$B$9:$B$68,Consolidado!BM$18,'TRAC D-155 82071'!$G$9:$G$68) -> 108 | BN23: =SUMIF('TRAC D-155 82071'!$B$9:$B$68,Consolidado!BN$18,'TRAC D-155 82071'!$G$9:$G$68) -> 89 | BO23: =SUMIF('TRAC D-155 82071'!$B$9:$B$68,Consolidado!BO$18,'TRAC D-155 82071'!$G$9:$G$68) -> 66 | BP23: =SUMIF('TRAC D-155 82071'!$B$9:$B$68,Consolidado!BP$18,'TRAC D-155 82071'!$G$9:$G$68) -> 76 | ... BT23: =SUMIF('TRAC D-155 82071'!$B$9:$B$68,Consolidado!BT$18,'TRAC D-155 82071'!$G$9:$G$68) -> 0 | BU23: =SUM(C23:BT23) -> 2310.3788
A24: 5 | B24: TRACTOR KOMATSU D155 AX | G24: =SUMIF('TRAC D-komatsu'!$B$10:$B$49,Consolidado!G$8,'TRAC D-komatsu'!$G$10:$G$49) -> 104 | H24: =SUMIF('TRAC D-komatsu'!$B$10:$B$49,Consolidado!H$8,'TRAC D-komatsu'!$G$10:$G$49) -> 34.52 | I24: =SUMIF('TRAC D-komatsu'!$B$10:$B$49,Consolidado!I$8,'TRAC D-komatsu'!$G$10:$G$49) -> 0 | J24: =SUMIF('TRAC D-komatsu'!$B$10:$B$49,Consolidado!J$8,'TRAC D-komatsu'!$G$10:$G$49) -> 106.33331 | K24: =SUMIF('TRAC D-komatsu'!$B$10:$B$49,Consolidado!K$8,'TRAC D-komatsu'!$G$10:$G$49) -> 120 | L24: =SUMIF('TRAC D-komatsu'!$B$10:$B$49,Consolidado!L$8,'TRAC D-komatsu'!$G$10:$G$49) -> 0 | M24: =SUMIF('TRAC D-komatsu'!$B$10:$B$49,Consolidado!M$8,'TRAC D-komatsu'!$G$10:$G$49) -> 0 | N24: =SUMIF('TRAC D-komatsu'!$B$10:$B$49,Consolidado!N$8,'TRAC D-komatsu'!$G$10:$G$49) -> 40.122 | O24: =SUMIF('TRAC D-komatsu'!$B$10:$B$49,Consolidado!O$8,'TRAC D-komatsu'!$G$10:$G$49) -> 0 | Q24: =SUMIF('TRAC D-komatsu'!$B$10:$B$49,Consolidado!Q$8,'TRAC D-komatsu'!$G$10:$G$49) -> 127.46 | R24: =SUMIF('TRAC D-komatsu'!$B$10:$B$49,Consolidado!R$8,'TRAC D-komatsu'!$G$10:$G$49) -> 70 | S24: =SUMIF('TRAC D-komatsu'!$B$10:$B$49,Consolidado!S$8,'TRAC D-komatsu'!$G$10:$G$49) -> 89 | T24: =SUMIF('TRAC D-komatsu'!$B$10:$B$49,Consolidado!T$8,'TRAC D-komatsu'!$G$10:$G$49) -> 107.92 | U24: =SUMIF('TRAC D-komatsu'!$B$10:$B$49,Consolidado!U$8,'TRAC D-komatsu'!$G$10:$G$49) -> 111.23 | V24: =SUMIF('TRAC D-komatsu'!$B$10:$B$49,Consolidado!V$8,'TRAC D-komatsu'!$G$10:$G$49) -> 93.16 | W24: =SUMIF('TRAC D-komatsu'!$B$10:$B$49,Consolidado!W$8,'TRAC D-komatsu'!$G$10:$G$49) -> 103.4 | X24: =SUMIF('TRAC D-komatsu'!$B$10:$B$49,Consolidado!X$8,'TRAC D-komatsu'!$G$10:$G$49) -> 0 | ... AG24: =SUMIF('TRAC D-komatsu'!$B$10:$B$49,Consolidado!AG$8,'TRAC D-komatsu'!$G$10:$G$49) -> 0 | BA24: =SUMIF('TRAC D-komatsu'!$B$10:$B$49,Consolidado!BA$8,'TRAC D-komatsu'!$G$10:$G$49) -> 0 | BB24: =SUMIF('TRAC D-komatsu'!$B$10:$B$49,Consolidado!BB$8,'TRAC D-komatsu'!$G$10:$G$49) -> 0 | BU24: =SUM(C24:BT24) -> 1192.1353
A25: TOTAL | C25: =SUM(C21:C24) -> 0 | D25: =SUM(D21:D24) -> 0 | E25: =SUM(E21:E24) -> 0 | F25: =SUM(F21:F24) -> 0 | G25: =SUM(G21:G24) -> 200.81021 | H25: =SUM(H21:H24) -> 178.52 | I25: =SUM(I21:I24) -> 0 | J25: =SUM(J21:J24) -> 373.33201 | ... O25: =SUM(O21:O24) -> 180 | Q25: =SUM(Q21:Q24) -> 277.17 | R25: =SUM(R21:R24) -> 153 | S25: =SUM(S21:S24) -> 165 | T25: =SUM(T21:T24) -> 107.92 | U25: =SUM(U21:U24) -> 206.69 | V25: =SUM(V21:V24) -> 155.64 | W25: =SUM(W21:W24) -> 189.7 | X25: =SUM(X21:X24) -> 0 | ... AC25: =SUM(AC21:AC24) -> 198.72 | AD25: =SUM(AD20:AD24) -> 233.155 | AE25: =SUM(AE20:AE24) -> 94.68 | AF25: =SUM(AF20:AF24) -> 90 | AG25: =SUM(AG20:AG24) -> 151.3 | AH25: =SUM(AH20:AH24) -> 0 | AI25: =SUM(AI20:AI24) -> 0 | AJ25: =SUM(AJ20:AJ24) -> 0 | AK25: =SUM(AK20:AK24) -> 0 | ... BU25: =SUM(BU20:BU24) -> 10688.228
A28: ITEM | B28: EQUIPO PESADO | D28: CONSUMO DIARIOS EN GALONES DE PETROLEO POR MAQUINA SECTOR TAMBO | BU28: TOTAL COMBUSTIBLE
C29: ANTERIOR | D29: 45845 | E29: 45846 | F29: 45847 | G29: 45848 | H29: 45849 | I29: 45850 | J29: 45852 | K29: 45853 | L29: 45854 | M29: 45855 | N29: 45856 | O29: 45857 | P29: 45858 | Q29: 45859 | R29: 45860 | S29: 45861 | T29: 45862 | U29: 45863 | V29: 45864 | W29: 45868 | X29: 45869 | Y29: 45870 | Z29: 45871 | AA29: 45872 | AB29: 45873 | AC29: 45874 | AD29: 45875 | AE29: 45876 | AF29: 45877 | AG29: 45878 | AH29: 45879 | AI29: 45880 | AJ29: 45881 | AK29: 45882 | AL29: 45883 | AM29: 45884 | AN29: 45885 | AO29: 45886 | AP29: 45887 | AQ29: 45888 | AR29: 45889 | AS29: 45890 | AT29: 45891 | AU29: 45892 | AV29: 45893 | AW29: 45894 | AX29: 45895 | AY29: 45896 | AZ29: 45897 | BA29: 45898 | BB29: 45899 | BC29: 45900 | BD29: 45901 | BE29: 45902 | BF29: 45903 | BG29: 45904 | BH29: 45905 | BI29: 45906 | BJ29: 45907 | BK29: 45908 | BL29: 45909 | BM29: 45910 | BN29: 45911 | BO29: 45912 | BP29: 45913 | BQ29: 45914 | BR29: 45915 | BS29: 45916 | BT29: 45923
A31: 1 | B31: EXCAVADORA KOMATSU 350PC | L31: =SUMIF('EXC-350PC'!$B$10:$B$80,Consolidado!L29,'EXC-350PC'!$G$10:$G$81) -> 154.99 | M31: =SUMIF('EXC-350PC'!$B$10:$B$80,Consolidado!M29,'EXC-350PC'!$G$10:$G$81) -> 50 | N31: =SUMIF('EXC-350PC'!$B$10:$B$80,Consolidado!N29,'EXC-350PC'!$G$10:$G$81) -> 156.6448 | O31: =SUMIF('EXC-350PC'!$B$10:$B$80,Consolidado!O29,'EXC-350PC'!$G$10:$G$81) -> 0 | Q31: =SUMIF('EXC-350PC'!$B$10:$B$80,Consolidado!Q29,'EXC-350PC'!$G$10:$G$81) -> 72.83 | R31: =SUMIF('EXC-350PC'!$B$10:$B$80,Consolidado!R29,'EXC-350PC'!$G$10:$G$81) -> 70.36 | S31: =SUMIF('EXC-350PC'!$B$10:$B$80,Consolidado!S29,'EXC-350PC'!$G$10:$G$81) -> 95 | T31: =SUMIF('EXC-350PC'!$B$10:$B$80,Consolidado!T29,'EXC-350PC'!$G$10:$G$81) -> 119.82 | U31: =SUMIF('EXC-350PC'!$B$10:$B$80,Consolidado!U29,'EXC-350PC'!$G$10:$G$81) -> 118.76 | V31: =SUMIF('EXC-350PC'!$B$10:$B$80,Consolidado!V29,'EXC-350PC'!$G$10:$G$81) -> 124.36 | W31: =SUMIF('EXC-350PC'!$B$10:$B$80,Consolidado!W29,'EXC-350PC'!$G$10:$G$81) -> 82 | X31: =SUMIF('EXC-350PC'!$B$10:$B$80,Consolidado!X29,'EXC-350PC'!$G$10:$G$81) -> 101.47 | ... AE31: =SUMIF('EXC-350PC'!$B$10:$B$80,Consolidado!AE29,'EXC-350PC'!$G$10:$G$81) -> 125.77 | AF31: =SUMIF('EXC-350PC'!$B$10:$B$81,Consolidado!AF29,'EXC-350PC'!$G$10:$G$81) -> 0 | AG31: =SUMIF('EXC-350PC'!$B$10:$B$80,Consolidado!AG29,'EXC-350PC'!$G$10:$G$81) -> 121.7 | AH31: =SUMIF('EXC-350PC'!$B$10:$B$80,Consolidado!AH29,'EXC-350PC'!$G$10:$G$81) -> 0 | AI31: =SUMIF('EXC-350PC'!$B$10:$B$80,Consolidado!AI29,'EXC-350PC'!$G$10:$G$81) -> 0 | AJ31: =SUMIF('EXC-350PC'!$B$10:$B$80,Consolidado!AJ29,'EXC-350PC'!$G$10:$G$81) -> 207.26 | AK31: =SUMIF('EXC-350PC'!$B$10:$B$80,Consolidado!AK29,'EXC-350PC'!$G$10:$G$81) -> 0 | AL31: =SUMIF('EXC-350PC'!$B$10:$B$80,Consolidado!AL29,'EXC-350PC'!$G$10:$G$81) -> 91.63 | AM31: =SUMIF('EXC-350PC'!$B$10:$B$80,Consolidado!AM29,'EXC-350PC'!$G$10:$G$81) -> 91.4 | AN31: =SUMIF('EXC-350PC'!$B$10:$B$80,Consolidado!AN29,'EXC-350PC'!$G$10:$G$81) -> 119 | ... BT31: =SUMIF('EXC-350PC'!$B$10:$B$80,Consolidado!BT29,'EXC-350PC'!$G$10:$G$81) -> 0 | BU31: =SUM(C31:BT31) -> 4162.6658
A32: 2 | B32: EXCAVADORA DOOSAN | AJ32: =SUMIF('EXC. DOOSAN'!$B$10:$B$70,Consolidado!AJ29,'EXC. DOOSAN'!$G$10:$G$70) -> -84.55 | AK32: =SUMIF('EXC. DOOSAN'!$B$10:$B$70,Consolidado!AK29,'EXC. DOOSAN'!$G$10:$G$70) -> 0 | AL32: =SUMIF('EXC. DOOSAN'!$B$10:$B$70,Consolidado!AL29,'EXC. DOOSAN'!$G$10:$G$70) -> 52 | AM32: =SUMIF('EXC. DOOSAN'!$B$10:$B$70,Consolidado!AM29,'EXC. DOOSAN'!$G$10:$G$70) -> 91 | AN32: =SUMIF('EXC. DOOSAN'!$B$10:$B$70,Consolidado!AN29,'EXC. DOOSAN'!$G$10:$G$70) -> 0 | AO32: =SUMIF('EXC. DOOSAN'!$B$10:$B$70,Consolidado!AO29,'EXC. DOOSAN'!$G$10:$G$70) -> 0 | AP32: =SUMIF('EXC. DOOSAN'!$B$10:$B$70,Consolidado!AP29,'EXC. DOOSAN'!$G$10:$G$70) -> 90 | AQ32: =SUMIF('EXC. DOOSAN'!$B$10:$B$70,Consolidado!AQ29,'EXC. DOOSAN'!$G$10:$G$70) -> 0 | ... BT32: =SUMIF('EXC. DOOSAN'!$B$10:$B$70,Consolidado!BT29,'EXC. DOOSAN'!$G$10:$G$70) -> 106.25 | BU32: =SUM(C32:BT32) -> 1459.32
A33: TOTAL | C33: =SUM(C31:C32) -> 0 | D33: =SUM(D31:D32) -> 0 | E33: =SUM(E31:E32) -> 0 | F33: =SUM(F31:F32) -> 0 | G33: =SUM(G31:G32) -> 0 | H33: =SUM(H31:H32) -> 0 | I33: =SUM(I31:I32) -> 0 | J33: =SUM(J31:J32) -> 0 | ... O33: =SUM(O31:O32) -> 0 | Q33: =SUM(Q31:Q32) -> 72.83 | R33: =SUM(R31:R32) -> 70.36 | S33: =SUM(S31:S32) -> 95 | T33: =SUM(T31:T32) -> 119.82 | U33: =SUM(U31:U32) -> 118.76 | V33: =SUM(V31:V32) -> 124.36 | W33: =SUM(W31:W32) -> 82 | X33: =SUM(X31:X32) -> 101.47 | ... BU33: =SUM(BU31:BU32) -> 5621.9858
B35: CONTROL | C35: ABASTECIDO | F35: =+F33+F25+F14 -> 115 | G35: =+G33+G25+G14 -> 309.51318 | H35: =+H33+H25+H14 -> 248.52 | I35: =+I33+I25+I14 -> 185 | J35: =+J33+J25+J14 -> 548.33201 | K35: =+K33+K25+K14 -> 350 | L35: =+L33+L25+L14 -> 334.99 | M35: =+M33+M25+M14 -> 220 | ... P35: =+P33+P25+P14 -> 0 | Q35: =+Q33+Q25+P36 -> 450 | R35: =+R33+R25+R14 -> 361.39 | S35: =+S33+S25+S14 -> 260 | T35: =+T33+T25+T14 -> 438.28 | U35: =+U33+U25+U14 -> 550.35 | V35: =+V33+V25+V14 -> 280 | W35: =+W33+W25+W14 -> 459.2 | X35: =+X33+X25+X14 -> 101.47 | Y35: =+Y33+Y25+Y14 -> 0 | ... BT35: =+BT33+BT25+BT14 -> 106.25
C36: COMPRADO | F36: 115 | G36: 309.5132 | H36: 248.52 | I36: 185 | J36: 548.33 | K36: 350 | L36: 334.99 | M36: 220 | N36: 376.65 | O36: 400 | P36: 100 | Q36: 460 | R36: =200+80+50 -> 330 | S36: =270 -> 270 | T36: =225+220 -> 445 | U36: =270+210+70 -> 550 | V36: 280 | W36: =280+180 -> 460 | X36: 100 | Z36: =280+280 -> 560 | AA36: =57.78+110+170 -> 337.78 | AB36: =280+100 -> 380 | AC36: =100+200 -> 300 | AD36: =120+81.415 -> 201.415 | AE36: 220 | AF36: 90 | AG36: 273 | AJ36: 122.71 | AL36: 348 | AM36: 312 | AN36: 200 | AP36: =220+180 -> 400 | AQ36: 240 | AR36: =240+100 -> 340 | AS36: 200 | AT36: =200+160 -> 360 | AU36: =240+100 -> 340 | AW36: =280+52 -> 332 | AX36: =100+200 -> 300 | AY36: =280+140 -> 420 | AZ36: =280+180 -> 460 | BA36: =280+100 -> 380 | BB36: 280 | BC36: =281+130 -> 411 | BD36: 280 | BE36: =280+48 -> 328 | BF36: =200+150 -> 350 | BG36: =240+120 -> 360 | BH36: =200+200 -> 400 | BI36: 280 | BJ36: =280+160 -> 440 | BL36: =280+130 -> 410 | BM36: =280+200 -> 480 | BN36: 220 | BO36: =200+100 -> 300 | BP36: =280+100 -> 380 | BR36: =220+280 -> 500 | BS36: 280 | BT36: 106.25
C37: SALDO | F37: =+F36-F35 -> 0 | G37: 0 | H37: =+H36-H35 -> 0 | I37: =+I36-I35 -> 0 | J37: 0 | K37: =+K36-K35 -> 0 | L37: =+L36-L35 -> 0 | M37: =+M36-M35 -> 0 | N37: 0 | O37: =+O36-O35 -> 0 | P37: 0 | Q37: =+Q36-Q35+P37 -> 10 | R37: =+R36-R35+Q37 -> -21.39 | S37: =+S35-S36 -> -10 | T37: =+T35-T36 -> -6.72 | U37: =+U35-U36 -> 0.35 | V37: =+V36-V35+U37 -> 0.35 | W37: =+W36-W35+V37 -> 1.15 | X37: =+X36-X35+W37 -> -0.32 | Y37: 0 | Z37: =+Z36-Z35+Y37 -> -6.24 | AA37: =+AA36-AA35 -> -0.001 | AB37: =+AB36-AB35 -> 31.97 | AC37: =+AC36-AC35+AB37 -> -5.42 | AD37: =+AD36-AD35+AC37 -> -37.16 | AE37: =+AE36-AE35+AD37 -> -37.61 | AF37: =+AF36-AF35+AE37 -> -37.61 | AG37: =+AG36-AG35+AF37 -> -37.61 | AH37: =+AH36-AH35+AG37 -> -37.61 | AI37: =+AI36-AI35+AH37 -> -37.61 | AJ37: =+AJ36-AJ35+AI37 -> -37.61 | ... AZ37: =+AZ36-AZ35+AY37 -> 20.61 | BA37: =+BA36-BA35 -> -2.63 | BB37: =+BB36-BB35 -> 1.66 | BC37: =+BC36-BC35 -> 2.89 | BD37: =+BD36-BD35 -> 25.11 | BE37: =+BE36-BE35+BD37 -> 42.99 | BF37: =+BF36-BF35+BE37 -> 27.19 | BG37: =+BG36-BG35+BF37 -> 15.41 | BH37: =+BH36-BH35+BG37 -> 35.6812 | BI37: =+BI36-BI35+BH37 -> 27.0712 | BJ37: =+BJ36-BJ35+BI37 -> 27.0712 | BK37: =+BK36-BK35+BJ37 -> 27.0712 | BL37: =+BL36-BL35+BK37 -> 27.0712 | ... BT37: =+BT36-BT35+BS37 -> 37.0712
A39: RESUMEN ACUMULADO GENERAL | BH39: .
A41: ITEM | B41: EQUIPO PESADO | D41: TOTAL ACUMULADO
A45: 2 | B45: TRACTOR D155 - AX CASTILLO | D45: =+BU11+BU22 -> 4387.9019
A46: 3 | B46: TRACTOR D155 - AX PALACIOS | D46: =+BU12+BU23 -> 3672.8747
A47: 4 | B47: CAMIONETA DE SERVICIO | D47: =+BU13 -> 47.86
A48: 7 | B48: TRACTOR KOMATSU D155 AX | C48: TRACTOR KOMATSU D155 AX | D48: =+BU24 -> 1192.1353
A49: 5 | B49: EXCAVADORA DOOSAN | C49: EXCAVADORA DOOSAN | D49: =+BU32+BU21 -> 2857.997
A50: 1 | B50: EXCAVADORA KOBELCO SK 350 | D50: =+BU10+BU20 -> 2890.165
A51: 8 | B51: EXCAVADORA KOMATSU 350PC | D51: =+BU31 -> 4162.6658
A52: 9
A53: TOTAL | D53: =SUM(D45:E52) -> 19211.6
D55: =+D53*14 -> 268962.4
AC57: =125+246 -> 371
